Workbook
Name Slicer_Diabetes_Status: #N/A
Name Slicer_Weight_Status: #N/A

Sheet Customer Names
A1: Customer ID | B1: name | D1: First Name | E1: Last Name | G1: Title
A2: Id1 | B2: Hawks, Ms. Kelly | D2: Hawks | E2: =H2&" "&I2 -> Kelly | G2: Ms. | H2: Kelly
A3: Id2 | B3: Lehner, Mr. Matthew D | D3: Lehner | E3: =H3&" "&I3 -> Matthew D | G3: Mr. | H3: Matthew | I3: D
A4: Id3 | B4: Lu, Mr. Phil | D4: Lu | E4: =H4&" "&I4 -> Phil | G4: Mr. | H4: Phil
A5: Id4 | B5: Osborne, Ms. Kelsey | D5: Osborne | E5: =H5&" "&I5 -> Kelsey | G5: Ms. | H5: Kelsey
A6: Id5 | B6: Kadala, Ms. Kristyn | D6: Kadala | E6: =H6&" "&I6 -> Kristyn | G6: Ms. | H6: Kristyn
A7: Id6 | B7: Baker, Mr. Russell B. | D7: Baker | E7: =H7&" "&I7 -> Russell B. | G7: Mr. | H7: Russell | I7: B.
A8: Id7 | B8: Macpherson, Mr. Scott | D8: Macpherson | E8: =H8&" "&I8 -> Scott | G8: Mr. | H8: Scott
A9: Id8 | B9: Hallman, Mr. Stephen | D9: Hallman | E9: =H9&" "&I9 -> Stephen | G9: Mr. | H9: Stephen
A10: Id9 | B10: Moran, Mr. Patrick R. | D10: Moran | E10: =H10&" "&I10 -> Patrick R. | G10: Mr. | H10: Patrick | I10: R.
A11: Id10 | B11: Benner, Ms. Brooke N. | D11: Benner | E11: =H11&" "&I11 -> Brooke N. | G11: Ms. | H11: Brooke | I11: N.
A12: Id11 | B12: Fierro Vargas, Ms. Paola Andrea | D12: Fierro Vargas | E12: =H12&" "&I12 -> Paola Andrea | G12: Ms. | H12: Paola | I12: Andrea
A13: Id12 | B13: Franz, Mr. David | D13: Franz | E13: =H13&" "&I13 -> David | G13: Mr. | H13: David
A14: Id13 | B14: Foster, Mr. Wade | D14: Foster | E14: =H14&" "&I14 -> Wade | G14: Mr. | H14: Wade
A15: Id14 | B15: Tenorio, Mr. Franklin | D15: Tenorio | E15: =H15&" "&I15 -> Franklin | G15: Mr. | H15: Franklin
A16: Id15 | B16: Rios, Ms. Leilani M. | D16: Rios | E16: =H16&" "&I16 -> Leilani M. | G16: Ms. | H16: Leilani | I16: M.
A17: Id16 | B17: Viau-Dupuis, Mr. Philippe | D17: Viau-Dupuis | E17: =H17&" "&I17 -> Philippe | G17: Mr. | H17: Philippe
A18: Id17 | B18: Cronin, Ms. Jennifer A. | D18: Cronin | E18: =H18&" "&I18 -> Jennifer A. | G18: Ms. | H18: Jennifer | I18: A.
A19: Id18 | B19: Noordstar, Ms. Christina M. | D19: Noordstar | E19: =H19&" "&I19 -> Christina M. | G19: Ms. | H19: Christina | I19: M.
A20: Id19 | B20: Boudalia, Mr. Said Sr. | D20: Boudalia | E20: =H20&" "&I20 -> Said Sr. | G20: Mr. | H20: Said | I20: Sr.
A21: Id20 | B21: Flor, Mr. John | D21: Flor | E21: =H21&" "&I21 -> John | G21: Mr. | H21: John
A22: Id21 | B22: Fennon, Mr. Myles | D22: Fennon | E22: =H22&" "&I22 -> Myles | G22: Mr. | H22: Myles
A23: Id22 | B23: Hribar, Ms. Madelyn C | D23: Hribar | E23: =H23&" "&I23 -> Madelyn C | G23: Ms. | H23: Madelyn | I23: C
A24: Id23 | B24: Tassello, Ms. Nicole | D24: Tassello | E24: =H24&" "&I24 -> Nicole | G24: Ms. | H24: Nicole
A25: Id24 | B25: Mauricette, Mr. Eric A. | D25: Mauricette | E25: =H25&" "&I25 -> Eric A. | G25: Mr. | H25: Eric | I25: A.
A26: Id25 | B26: Garcia, Mr. Emiliano I. | D26: Garcia | E26: =H26&" "&I26 -> Emiliano I. | G26: Mr. | H26: Emiliano | I26: I.
A27: Id26 | B27: Airoldi, Mr. Adam | D27: Airoldi | E27: =H27&" "&I27 -> Adam | G27: Mr. | H27: Adam
A28: Id27 | B28: Cater-Cyker, Mr. Zach | D28: Cater-Cyker | E28: =H28&" "&I28 -> Zach | G28: Mr. | H28: Zach
A29: Id28 | B29: Hamm, Ms. Stephanie W. | D29: Hamm | E29: =H29&" "&I29 -> Stephanie W. | G29: Ms. | H29: Stephanie | I29: W.
A30: Id29 | B30: Cox, Mr. Stephen | D30: Cox | E30: =H30&" "&I30 -> Stephen | G30: Mr. | H30: Stephen
A31: Id30 | B31: Sachrajda, Ms. Natalie | D31: Sachrajda | E31: =H31&" "&I31 -> Natalie | G31: Ms. | H31: Natalie
A32: Id31 | B32: Gareri, Ms. Nicole J. | D32: Gareri | E32: =H32&" "&I32 -> Nicole J. | G32: Ms. | H32: Nicole | I32: J.
A33: Id32 | B33: Welch, Mr. Jefferson D | D33: Welch | E33: =H33&" "&I33 -> Jefferson D | G33: Mr. | H33: Jefferson | I33: D
A34: Id33 | B34: Prindiville, Mr. Brendan D. | D34: Prindiville | E34: =H34&" "&I34 -> Brendan D. | G34: Mr. | H34: Brendan | I34: D.
A35: Id34 | B35: Kincaid, Ms. Courtney | D35: Kincaid | E35: =H35&" "&I35 -> Courtney | G35: Ms. | H35: Courtney
A36: Id35 | B36: Bruestle, Ms. Sydney L. | D36: Bruestle | E36: =H36&" "&I36 -> Sydney L. | G36: Ms. | H36: Sydney | I36: L.
A37: Id36 | B37: Lachance, Mr. Julien | D37: Lachance | E37: =H37&" "&I37 -> Julien | G37: Mr. | H37: Julien
A38: Id37 | B38: Eason, Mr. Ryan M | D38: Eason | E38: =H38&" "&I38 -> Ryan M | G38: Mr. | H38: Ryan | I38: M
A39: Id38 | B39: Grummon, Ms. Anna H. | D39: Grummon | E39: =H39&" "&I39 -> Anna H. | G39: Ms. | H39: Anna | I39: H.
A40: Id39 | B40: Vanwechel, Ms. Samantha | D40: Vanwechel | E40: =H40&" "&I40 -> Samantha | G40: Ms. | H40: Samantha
...

Sheet Medical Examinations
A1: Customer ID | B1: BMI | C1: HBA1C | D1: Heart Issues | E1: Any Transplants | F1: Cancer history | G1: NumberOfMajorSurgeries | H1: smoker | J1: Weight Status | K1: Diabetes Status | M1: Medical Examination | N1: Missing value
A2: Id1 | B2: 47.41 | C2: 7.47 | D2: NO | E2: NO | F2: NO | G2: 0 | H2: Yes | I2: =COUNTIF(H:H,"?") -> 0 | J2: =IF(B3>=30,"Obesity",IF(B3>=25,"Over Weight",IF(B3>=18.5,"NormalWeight","UnderWeight"))) -> Obesity | K2: =IF(C2<5.7,"Normal",IF(C2<6.5,"Pre-Diabetes","Diabetes")) -> Diabetes | M2: Customer ID | N2: 0
A3: Id2 | B3: 30.36 | C3: 5.77 | D3: NO | E3: NO | F3: NO | G3: 0 | H3: Yes | J3: =IF(B4>=30,"Obesity",IF(B4>=25,"Over Weight",IF(B4>=18.5,"NormalWeight","UnderWeight"))) -> Obesity | K3: =IF(C3<5.7,"Normal",IF(C3<6.5,"Pre-Diabetes","Diabetes")) -> Pre-Diabetes | M3: BMI | N3: 0
A4: Id3 | B4: 34.485 | C4: 11.87 | D4: Yes | E4: NO | F4: NO | G4: 2 | H4: Yes | J4: =IF(B5>=30,"Obesity",IF(B5>=25,"Over Weight",IF(B5>=18.5,"NormalWeight","UnderWeight"))) -> Obesity | K4: =IF(C4<5.7,"Normal",IF(C4<6.5,"Pre-Diabetes","Diabetes")) -> Diabetes | M4: HBA1C | N4: 0
A5: Id4 | B5: 38.095 | C5: 6.05 | D5: NO | E5: NO | F5: NO | G5: 0 | H5: Yes | J5: =IF(B6>=30,"Obesity",IF(B6>=25,"Over Weight",IF(B6>=18.5,"NormalWeight","UnderWeight"))) -> Obesity | K5: =IF(C5<5.7,"Normal",IF(C5<6.5,"Pre-Diabetes","Diabetes")) -> Pre-Diabetes | M5: Heart Issues | N5: 0
A6: Id5 | B6: 35.53 | C6: 5.45 | D6: NO | E6: NO | F6: NO | G6: 0 | H6: Yes | J6: =IF(B7>=30,"Obesity",IF(B7>=25,"Over Weight",IF(B7>=18.5,"NormalWeight","UnderWeight"))) -> Obesity | K6: =IF(C6<5.7,"Normal",IF(C6<6.5,"Pre-Diabetes","Diabetes")) -> Normal | M6: Any Transplants | N6: 0
A7: Id6 | B7: 32.8 | C7: 6.59 | D7: NO | E7: NO | F7: NO | G7: 0 | H7: Yes | J7: =IF(B8>=30,"Obesity",IF(B8>=25,"Over Weight",IF(B8>=18.5,"NormalWeight","UnderWeight"))) -> Obesity | K7: =IF(C7<5.7,"Normal",IF(C7<6.5,"Pre-Diabetes","Diabetes")) -> Diabetes | M7: Cancer history | N7: 0
A8: Id7 | B8: 36.4 | C8: 6.07 | D8: NO | E8: NO | F8: NO | G8: 0 | H8: Yes | J8: =IF(B9>=30,"Obesity",IF(B9>=25,"Over Weight",IF(B9>=18.5,"NormalWeight","UnderWeight"))) -> Obesity | K8: =IF(C8<5.7,"Normal",IF(C8<6.5,"Pre-Diabetes","Diabetes")) -> Pre-Diabetes | M8: Number of majour surgeries | N8: 0
A9: Id8 | B9: 36.96 | C9: 7.93 | D9: NO | E9: NO | F9: NO | G9: 3 | H9: Yes | J9: =IF(B10>=30,"Obesity",IF(B10>=25,"Over Weight",IF(B10>=18.5,"NormalWeight","UnderWeight"))) -> Obesity | K9: =IF(C9<5.7,"Normal",IF(C9<6.5,"Pre-Diabetes","Diabetes")) -> Diabetes | M9: smoker | N9: 2
A10: Id9 | B10: 41.14 | C10: 9.58 | D10: Yes | E10: NO | F10: Yes | G10: 1 | H10: Yes | J10: =IF(B11>=30,"Obesity",IF(B11>=25,"Over Weight",IF(B11>=18.5,"NormalWeight","UnderWeight"))) -> Obesity | K10: =IF(C10<5.7,"Normal",IF(C10<6.5,"Pre-Diabetes","Diabetes")) -> Diabetes
A11: Id10 | B11: 38.06 | C11: 10.79 | D11: NO | E11: NO | F11: NO | G11: 0 | H11: Yes | J11: =IF(B12>=30,"Obesity",IF(B12>=25,"Over Weight",IF(B12>=18.5,"NormalWeight","UnderWeight"))) -> Obesity | K11: =IF(C11<5.7,"Normal",IF(C11<6.5,"Pre-Diabetes","Diabetes")) -> Diabetes
A12: Id11 | B12: 37.7 | C12: 5.96 | D12: Yes | E12: NO | F12: NO | G12: 2 | H12: Yes | J12: =IF(B13>=30,"Obesity",IF(B13>=25,"Over Weight",IF(B13>=18.5,"NormalWeight","UnderWeight"))) -> Obesity | K12: =IF(C12<5.7,"Normal",IF(C12<6.5,"Pre-Diabetes","Diabetes")) -> Pre-Diabetes
A13: Id12 | B13: 42.13 | C13: 11.9 | D13: NO | E13: NO | F13: NO | G13: 0 | H13: Yes | J13: =IF(B14>=30,"Obesity",IF(B14>=25,"Over Weight",IF(B14>=18.5,"NormalWeight","UnderWeight"))) -> Obesity | K13: =IF(C13<5.7,"Normal",IF(C13<6.5,"Pre-Diabetes","Diabetes")) -> Diabetes
A14: Id13 | B14: 40.92 | C14: 8.41 | D14: NO | E14: NO | F14: NO | G14: 0 | H14: Yes | J14: =IF(B15>=30,"Obesity",IF(B15>=25,"Over Weight",IF(B15>=18.5,"NormalWeight","UnderWeight"))) -> Obesity | K14: =IF(C14<5.7,"Normal",IF(C14<6.5,"Pre-Diabetes","Diabetes")) -> Diabetes
A15: Id14 | B15: 40.565 | C15: 7.02 | D15: NO | E15: NO | F15: NO | G15: 0 | H15: Yes | J15: =IF(B16>=30,"Obesity",IF(B16>=25,"Over Weight",IF(B16>=18.5,"NormalWeight","UnderWeight"))) -> Obesity | K15: =IF(C15<5.7,"Normal",IF(C15<6.5,"Pre-Diabetes","Diabetes")) -> Diabetes
A16: Id15 | B16: 36.385 | C16: 7.59 | D16: Yes | E16: NO | F16: NO | G16: 2 | H16: Yes | J16: =IF(B17>=30,"Obesity",IF(B17>=25,"Over Weight",IF(B17>=18.5,"NormalWeight","UnderWeight"))) -> Obesity | K16: =IF(C16<5.7,"Normal",IF(C16<6.5,"Pre-Diabetes","Diabetes")) -> Diabetes
A17: Id16 | B17: 39.9 | C17: 11.32 | D17: NO | E17: NO | F17: NO | G17: 0 | H17: Yes | J17: =IF(B18>=30,"Obesity",IF(B18>=25,"Over Weight",IF(B18>=18.5,"NormalWeight","UnderWeight"))) -> Obesity | K17: =IF(C17<5.7,"Normal",IF(C17<6.5,"Pre-Diabetes","Diabetes")) -> Diabetes
A18: Id17 | B18: 33.8 | C18: 7.67 | D18: NO | E18: NO | F18: NO | G18: 3 | H18: Yes | J18: =IF(B19>=30,"Obesity",IF(B19>=25,"Over Weight",IF(B19>=18.5,"NormalWeight","UnderWeight"))) -> Obesity | K18: =IF(C18<5.7,"Normal",IF(C18<6.5,"Pre-Diabetes","Diabetes")) -> Diabetes
A19: Id18 | B19: 36.765 | C19: 7.29 | D19: Yes | E19: NO | F19: Yes | G19: 1 | H19: Yes | J19: =IF(B20>=30,"Obesity",IF(B20>=25,"Over Weight",IF(B20>=18.5,"NormalWeight","UnderWeight"))) -> Obesity | K19: =IF(C19<5.7,"Normal",IF(C19<6.5,"Pre-Diabetes","Diabetes")) -> Diabetes
A20: Id19 | B20: 36.955 | C20: 4.72 | D20: Yes | E20: NO | F20: NO | G20: 1 | H20: Yes | J20: =IF(B21>=30,"Obesity",IF(B21>=25,"Over Weight",IF(B21>=18.5,"NormalWeight","UnderWeight"))) -> Obesity | K20: =IF(C20<5.7,"Normal",IF(C20<6.5,"Pre-Diabetes","Diabetes")) -> Normal
A21: Id20 | B21: 42.9 | C21: 11.41 | D21: NO | E21: NO | F21: NO | G21: 0 | H21: Yes | J21: =IF(B22>=30,"Obesity",IF(B22>=25,"Over Weight",IF(B22>=18.5,"NormalWeight","UnderWeight"))) -> Obesity | K21: =IF(C21<5.7,"Normal",IF(C21<6.5,"Pre-Diabetes","Diabetes")) -> Diabetes
... A2336: Id2335 | B2336: 17.58 | C2336: 4.51 | D2336: NO | E2336: NO | F2336: NO | G2336: 1 | H2336: NO | J2336: =IF(B2337>=30,"Obesity",IF(B2337>=25,"Over Weight",IF(B2337>=18.5,"NormalWeight","UnderWeight"))) -> UnderWeight | K2336: =IF(C2336<5.7,"Normal",IF(C2336<6.5,"Pre-Diabetes","Diabetes")) -> Normal

Sheet Hospitalisation Details
A1: Customer ID | B1: year | C1: month | D1: date | E1: children | F1: charges | G1: Hospital tier | H1: City tier | I1: State ID | K1: Year and Date | L1: Date Of Birth | M1: DOB With AGE | O1: Hospitalisation Details | P1: Missing values
A2: Id2335 | B2: 1992 | C2: Jul | D2: 9 | E2: 0 | F2: 563.84 | G2: tier - 2 | H2: tier - 3 | I2: R1013 | J2: =COUNTIF(A:A,"?") -> 6 | K2: =B2&"-"&D2 -> 1992-9 | L2: =D2&"-"&C2&"-"&B2 -> 9-Jul-1992 | M2: =DATEDIF(L2,DATE(2023,6,8),"Y") -> 30 | O2: Customer ID | P2: 6
A3: Id2334 | B3: 1992 | C3: Nov | D3: 30 | E3: 0 | F3: 570.62 | G3: tier - 2 | H3: tier - 1 | I3: R1013 | J3: =COUNTIF(B:B,"?") -> 0 | K3: =B3&"-"&D3 -> 1992-30 | L3: =D3&"-"&C3&"-"&B3 -> 30-Nov-1992 | M3: =DATEDIF(L3,DATE(2023,6,8),"Y") -> 30 | O3: year | P3: 2
A4: Id2333 | B4: 1993 | C4: Jun | D4: 30 | E4: 0 | F4: 600 | G4: tier - 2 | H4: tier - 1 | I4: R1013 | J4: =COUNTIF(C:C,"?") -> 0 | K4: =B4&"-"&D4 -> 1993-30 | L4: =D4&"-"&C4&"-"&B4 -> 30-Jun-1993 | M4: =DATEDIF(L4,DATE(2023,6,8),"Y") -> 29 | O4: month | P4: 3
A5: Id2332 | B5: 1992 | C5: Sep | D5: 13 | E5: 0 | F5: 604.54 | G5: tier - 3 | H5: tier - 3 | I5: R1013 | J5: =COUNTIF(D:D,"?") -> 0 | K5: =B5&"-"&D5 -> 1992-13 | L5: =D5&"-"&C5&"-"&B5 -> 13-Sep-1992 | M5: =DATEDIF(L5,DATE(2023,6,8),"Y") -> 30 | O5: date | P5: 0
A6: Id2331 | B6: 1998 | C6: Jul | D6: 27 | E6: 0 | F6: 637.26 | G6: tier - 3 | H6: tier - 3 | I6: R1013 | J6: =COUNTIF(E:E,"?") -> 0 | K6: =B6&"-"&D6 -> 1998-27 | L6: =D6&"-"&C6&"-"&B6 -> 27-Jul-1998 | M6: =DATEDIF(L6,DATE(2023,6,8),"Y") -> 24 | O6: children | P6: 0
A7: Id2330 | B7: 2001 | C7: Nov | D7: 20 | E7: 0 | F7: 646.14 | G7: tier - 3 | H7: tier - 3 | I7: R1012 | J7: =COUNTIF(F:F,"?") -> 0 | K7: =B7&"-"&D7 -> 2001-20 | L7: =D7&"-"&C7&"-"&B7 -> 20-Nov-2001 | M7: =DATEDIF(L7,DATE(2023,6,8),"Y") -> 21 | O7: charges | P7: 0
A8: Id2329 | B8: 1993 | C8: Jun | D8: 1 | E8: 0 | F8: 650 | G8: tier - 3 | H8: tier - 3 | I8: R1013 | J8: =COUNTIF(G:G,"?") -> 0 | K8: =B8&"-"&D8 -> 1993-1 | L8: =D8&"-"&C8&"-"&B8 -> 1-Jun-1993 | M8: =DATEDIF(L8,DATE(2023,6,8),"Y") -> 30 | O8: hospital tier | P8: 1
A9: Id2328 | B9: 1995 | C9: Jul | D9: 4 | E9: 0 | F9: 650 | G9: tier - 3 | H9: tier - 3 | I9: R1013 | J9: =COUNTIF(H:H,"?") -> 0 | K9: =B9&"-"&D9 -> 1995-4 | L9: =D9&"-"&C9&"-"&B9 -> 4-Jul-1995 | M9: =DATEDIF(L9,DATE(2023,6,8),"Y") -> 27 | O9: city tier | P9: 1
A10: Id2327 | B10: 2002 | C10: Nov | D10: 29 | E10: 0 | F10: 668 | G10: tier - 3 | H10: tier - 2 | I10: R1012 | J10: =COUNTIF(I:I,"?") -> 0 | K10: =B10&"-"&D10 -> 2002-29 | L10: =D10&"-"&C10&"-"&B10 -> 29-Nov-2002 | M10: =DATEDIF(L10,DATE(2023,6,8),"Y") -> 20 | O10: state ID | P10: 2
A11: Id2326 | B11: 1997 | C11: Nov | D11: 9 | E11: 0 | F11: 670 | G11: tier - 3 | H11: tier - 3 | I11: R1013 | K11: =B11&"-"&D11 -> 1997-9 | L11: =D11&"-"&C11&"-"&B11 -> 9-Nov-1997 | M11: =DATEDIF(L11,DATE(2023,6,8),"Y") -> 25
A12: Id2325 | B12: 2001 | C12: Sep | D12: 12 | E12: 0 | F12: 687.54 | G12: tier - 3 | H12: tier - 2 | I12: R1013 | K12: =B12&"-"&D12 -> 2001-12 | L12: =D12&"-"&C12&"-"&B12 -> 12-Sep-2001 | M12: =DATEDIF(L12,DATE(2023,6,8),"Y") -> 21 | O12: Most frequently occuring values in
A13: Id2324 | B13: 1999 | C13: Dec | D13: 26 | E13: 0 | F13: 700 | G13: tier - 2 | H13: tier - 3 | I13: R1013 | K13: =B13&"-"&D13 -> 1999-26 | L13: =D13&"-"&C13&"-"&B13 -> 26-Dec-1999 | M13: =DATEDIF(L13,DATE(2023,6,8),"Y") -> 23 | O13: Hospital tier | P13: tier -2
A14: Id2323 | B14: 1999 | C14: Dec | D14: 14 | E14: 0 | F14: 722.99 | G14: tier - 3 | H14: tier - 1 | I14: R1013 | K14: =B14&"-"&D14 -> 1999-14 | L14: =D14&"-"&C14&"-"&B14 -> 14-Dec-1999 | M14: =DATEDIF(L14,DATE(2023,6,8),"Y") -> 23 | O14: city tier | P14: tier -2
A15: Id2322 | B15: 2002 | C15: Sep | D15: 19 | E15: 0 | F15: 750 | G15: tier - 3 | H15: tier - 1 | I15: R1012 | K15: =B15&"-"&D15 -> 2002-19 | L15: =D15&"-"&C15&"-"&B15 -> 19-Sep-2002 | M15: =DATEDIF(L15,DATE(2023,6,8),"Y") -> 20 | O15: Smoker | P15: No
A16: Id2321 | B16: 1993 | C16: Aug | D16: 9 | E16: 0 | F16: 760 | G16: tier - 3 | H16: tier - 1 | I16: R1013 | K16: =B16&"-"&D16 -> 1993-9 | L16: =D16&"-"&C16&"-"&B16 -> 9-Aug-1993 | M16: =DATEDIF(L16,DATE(2023,6,8),"Y") -> 29
A17: Id2320 | B17: 1996 | C17: Oct | D17: 22 | E17: 0 | F17: 760 | G17: tier - 3 | H17: tier - 3 | I17: R1013 | K17: =B17&"-"&D17 -> 1996-22 | L17: =D17&"-"&C17&"-"&B17 -> 22-Oct-1996 | M17: =DATEDIF(L17,DATE(2023,6,8),"Y") -> 26
A18: Id2319 | B18: 1993 | C18: Jun | D18: 28 | E18: 0 | F18: 770 | G18: tier - 3 | H18: tier - 3 | I18: R1013 | K18: =B18&"-"&D18 -> 1993-28 | L18: =D18&"-"&C18&"-"&B18 -> 28-Jun-1993 | M18: =DATEDIF(L18,DATE(2023,6,8),"Y") -> 29
A19: Id2318 | B19: 1996 | C19: Sep | D19: 18 | E19: 0 | F19: 770.38 | G19: tier - 3 | H19: tier - 2 | I19: R1012 | K19: =B19&"-"&D19 -> 1996-18 | L19: =D19&"-"&C19&"-"&B19 -> 18-Sep-1996 | M19: =DATEDIF(L19,DATE(2023,6,8),"Y") -> 26
A20: Id2317 | B20: 1995 | C20: Dec | D20: 7 | E20: 0 | F20: 773.54 | G20: tier - 3 | H20: tier - 2 | I20: R1013 | K20: =B20&"-"&D20 -> 1995-7 | L20: =D20&"-"&C20&"-"&B20 -> 7-Dec-1995 | M20: =DATEDIF(L20,DATE(2023,6,8),"Y") -> 27
A21: Id2316 | B21: 2004 | C21: Oct | D21: 7 | E21: 0 | F21: 830.52 | G21: tier - 3 | H21: tier - 2 | I21: R1011 | K21: =B21&"-"&D21 -> 2004-7 | L21: =D21&"-"&C21&"-"&B21 -> 7-Oct-2004 | M21: =DATEDIF(L21,DATE(2023,6,8),"Y") -> 18
A22: Id2315 | B22: 2000 | C22: Nov | D22: 18 | E22: 0 | F22: 865.41 | G22: tier - 3 | H22: tier - 1 | I22: R1013 | K22: =B22&"-"&D22 -> 2000-18 | L22: =D22&"-"&C22&"-"&B22 -> 18-Nov-2000 | M22: =DATEDIF(L22,DATE(2023,6,8),"Y") -> 22
A23: Id2314 | B23: 1993 | C23: Nov | D23: 27 | E23: 0 | F23: 896.21 | G23: tier - 3 | H23: tier - 1 | I23: R1013 | K23: =B23&"-"&D23 -> 1993-27 | L23: =D23&"-"&C23&"-"&B23 -> 27-Nov-1993 | M23: =DATEDIF(L23,DATE(2023,6,8),"Y") -> 29
A24: Id2313 | B24: 1994 | C24: Oct | D24: 30 | E24: 0 | F24: 915.07 | G24: tier - 3 | H24: tier - 1 | I24: R1013 | K24: =B24&"-"&D24 -> 1994-30 | L24: =D24&"-"&C24&"-"&B24 -> 30-Oct-1994 | M24: =DATEDIF(L24,DATE(2023,6,8),"Y") -> 28
A25: Id2312 | B25: 1995 | C25: Oct | D25: 28 | E25: 0 | F25: 928.59 | G25: tier - 3 | H25: tier - 1 | I25: R1013 | K25: =B25&"-"&D25 -> 1995-28 | L25: =D25&"-"&C25&"-"&B25 -> 28-Oct-1995 | M25: =DATEDIF(L25,DATE(2023,6,8),"Y") -> 27
A26: Id2311 | B26: 2001 | C26: Aug | D26: 19 | E26: 0 | F26: 964.71 | G26: tier - 3 | H26: tier - 2 | I26: R1013 | K26: =B26&"-"&D26 -> 2001-19 | L26: =D26&"-"&C26&"-"&B26 -> 19-Aug-2001 | M26: =DATEDIF(L26,DATE(2023,6,8),"Y") -> 21
A27: Id2310 | B27: 1994 | C27: Nov | D27: 22 | E27: 0 | F27: 1006.65 | G27: tier - 3 | H27: tier - 2 | I27: R1013 | K27: =B27&"-"&D27 -> 1994-22 | L27: =D27&"-"&C27&"-"&B27 -> 22-Nov-1994 | M27: =DATEDIF(L27,DATE(2023,6,8),"Y") -> 28
... A1050: Id1290 | B1050: 1977 | C1050: Jul | D1050: 26 | E1050: 2 | F1050: 8527.53 | G1050: tier - 2 | H1050: tier - 2 | I1050: R1013 | K1050: =B1050&"-"&D1050 -> 1977-26 | L1050: =D1050&"-"&C1050&"-"&B1050 -> 26-Jul-1977 | M1050: =DATEDIF(L1050,DATE(2023,6,8),"Y") -> 45
A1051: Id1289 | B1051: =AVERAGE(B1045:B1050) -> 1980 | C1051: Jul | D1051: 24 | E1051: 0 | F1051: 8534.67 | G1051: tier - 2 | H1051: tier - 3 | I1051: R1024 | K1051: =B1051&"-"&D1051 -> 1980-24 | L1051: =D1051&"-"&C1051&"-"&B1051 -> 24-Jul-1980 | M1051: =DATEDIF(L1051,DATE(2023,6,8),"Y") -> 42
A1052: Id1288 | B1052: 1981 | C1052: Dec | D1052: 27 | E1052: 3 | F1052: 8538.29 | G1052: tier - 2 | H1052: tier - 3 | I1052: R1024 | K1052: =B1052&"-"&D1052 -> 1981-27 | L1052: =D1052&"-"&C1052&"-"&B1052 -> 27-Dec-1981 | M1052: =DATEDIF(L1052,DATE(2023,6,8),"Y") -> 41
A1053: Id1287 | B1053: 1975 | C1053: Nov | D1053: 6 | E1053: 1 | F1053: 8539.67 | G1053: tier - 2 | H1053: tier - 3 | I1053: R1011 | K1053: =B1053&"-"&D1053 -> 1975-6 | L1053: =D1053&"-"&C1053&"-"&B1053 -> 6-Nov-1975 | M1053: =DATEDIF(L1053,DATE(2023,6,8),"Y") -> 47
A1054: Id1286 | B1054: =AVERAGE(B1052:B1053) -> 1978 | C1054: Dec | D1054: 12 | E1054: 1 | F1054: 8547.69 | G1054: tier - 2 | H1054: tier - 1 | I1054: R1013 | K1054: =B1054&"-"&D1054 -> 1978-12 | L1054: =D1054&"-"&C1054&"-"&B1054 -> 12-Dec-1978 | M1054: =DATEDIF(L1054,DATE(2023,6,8),"Y") -> 44
A1055: Id1285 | B1055: 1975 | C1055: Aug | D1055: 6 | E1055: 1 | F1055: 8551.35 | G1055: tier - 2 | H1055: tier - 2 | I1055: R1011 | K1055: =B1055&"-"&D1055 -> 1975-6 | L1055: =D1055&"-"&C1055&"-"&B1055 -> 6-Aug-1975 | M1055: =DATEDIF(L1055,DATE(2023,6,8),"Y") -> 47
A1056: Id1284 | B1056: 1975 | C1056: Aug | D1056: 21 | E1056: 1 | F1056: 8556.91 | G1056: tier - 2 | H1056: tier - 1 | I1056: R1011 | K1056: =B1056&"-"&D1056 -> 1975-21 | L1056: =D1056&"-"&C1056&"-"&B1056 -> 21-Aug-1975 | M1056: =DATEDIF(L1056,DATE(2023,6,8),"Y") -> 47
A1057: Id1283 | B1057: 1988 | C1057: Sep | D1057: 21 | E1057: 3 | F1057: 8567.25 | G1057: tier - 2 | H1057: tier - 1 | I1057: R1012 | K1057: =B1057&"-"&D1057 -> 1988-21 | L1057: =D1057&"-"&C1057&"-"&B1057 -> 21-Sep-1988 | M1057: =DATEDIF(L1057,DATE(2023,6,8),"Y") -> 34
A1058: Id1282 | B1058: 1975 | C1058: Sep | D1058: 26 | E1058: 1 | F1058: 8569.86 | G1058: tier - 2 | H1058: tier - 3 | I1058: R1013 | K1058: =B1058&"-"&D1058 -> 1975-26 | L1058: =D1058&"-"&C1058&"-"&B1058 -> 26-Sep-1975 | M1058: =DATEDIF(L1058,DATE(2023,6,8),"Y") -> 47
A1059: Id1281 | B1059: 1982 | C1059: Dec | D1059: 6 | E1059: 3 | F1059: 8572.04 | G1059: tier - 2 | H1059: tier - 2 | I1059: R1021 | K1059: =B1059&"-"&D1059 -> 1982-6 | L1059: =D1059&"-"&C1059&"-"&B1059 -> 6-Dec-1982 | M1059: =DATEDIF(L1059,DATE(2023,6,8),"Y") -> 40
A1060: Id1280 | B1060: 1987 | C1060: Nov | D1060: 11 | E1060: 3 | F1060: 8573.3 | G1060: tier - 2 | H1060: tier - 2 | I1060: R1021 | K1060: =B1060&"-"&D1060 -> 1987-11 | L1060: =D1060&"-"&C1060&"-"&B1060 -> 11-Nov-1987 | M1060: =DATEDIF(L1060,DATE(2023,6,8),"Y") -> 35
A1061: Id1279 | B1061: 1983 | C1061: Dec | D1061: 30 | E1061: 5 | F1061: 8582.3 | G1061: tier - 2 | H1061: tier - 1 | I1061: R1013 | K1061: =B1061&"-"&D1061 -> 1983-30 | L1061: =D1061&"-"&C1061&"-"&B1061 -> 30-Dec-1983 | M1061: =DATEDIF(L1061,DATE(2023,6,8),"Y") -> 39
A1062: Id1278 | B1062: 1983 | C1062: Jul | D1062: 25 | E1062: 5 | F1062: 8596.83 | G1062: tier - 2 | H1062: tier - 3 | I1062: R1013 | K1062: =B1062&"-"&D1062 -> 1983-25 | L1062: =D1062&"-"&C1062&"-"&B1062 -> 25-Jul-1983 | M1062: =DATEDIF(L1062,DATE(2023,6,8),"Y") -> 39
...

Sheet Sheet2
E2: HEALTHCARE ANALYSIS

Sheet Health Care
A1: Customer ID | B1: First Name | C1: BMI | D1: HBA1C | E1: Heart Issues | F1: Any Transplant | G1: Cancer History | H1: Number of Major surgeries | I1: Smoker | J1: Weight Status | K1: Diabetes Status | L1: Date Of Birth | M1: Charges | N1: Hospital Tier | O1: City Tier | P1: State ID | Q1: AGE
A2: Id1 | B2: =VLOOKUP(A2,'Customer Names'!A$1:D2337,4,0) -> Hawks | C2: =VLOOKUP(A2,'Medical Examinations'!A$1:B2337,2,0) -> 47.41 | D2: =VLOOKUP(A2,'Medical Examinations'!A$1:C2338,3,0) -> 7.47 | E2: =VLOOKUP(A2,'Medical Examinations'!A$1:D2337,4,0) -> NO | F2: =VLOOKUP(A2,'Medical Examinations'!A$1:E2337,5,0) -> NO | G2: =VLOOKUP(A2,'Medical Examinations'!A$1:F2337,6,0) -> NO | H2: =VLOOKUP(A2,'Medical Examinations'!A$1:G2337,7,0) -> 0 | I2: =VLOOKUP(A2,'Medical Examinations'!A$1:H2336,8,0) -> Yes | J2: =VLOOKUP(A2,'Medical Examinations'!A$1:J2337,10,0) -> Obesity | K2: =VLOOKUP(A2,'Medical Examinations'!A$1:K2336,11,0) -> Diabetes | L2: =VLOOKUP(A2,'Hospitalisation Details'!A$1:L2344,12,0) -> 12-Oct-1968 | M2: =VLOOKUP(A2,'Hospitalisation Details'!A$1:F2345,6,0) -> 63770.43 | N2: =VLOOKUP(A2,'Hospitalisation Details'!A$1:G2344,7,0) -> tier - 1 | O2: =VLOOKUP(A2,'Hospitalisation Details'!A$1:H2345,8,0) -> tier - 3 | P2: =VLOOKUP(A2,'Hospitalisation Details'!A$1:I2345,9,0) -> R1013 | Q2: =VLOOKUP(A2,'Hospitalisation Details'!A$1:M2345,13,0) -> 54
A3: Id2 | B3: =VLOOKUP(A3,'Customer Names'!A$1:D2338,4,0) -> Lehner | C3: =VLOOKUP(A3,'Medical Examinations'!A$1:B2338,2,0) -> 30.36 | D3: =VLOOKUP(A3,'Medical Examinations'!A$1:C2339,3,0) -> 5.77 | E3: =VLOOKUP(A3,'Medical Examinations'!A$1:D2338,4,0) -> NO | F3: =VLOOKUP(A3,'Medical Examinations'!A$1:E2338,5,0) -> NO | G3: =VLOOKUP(A3,'Medical Examinations'!A$1:F2338,6,0) -> NO | H3: =VLOOKUP(A3,'Medical Examinations'!A$1:G2338,7,0) -> 0 | I3: =VLOOKUP(A3,'Medical Examinations'!A$1:H2337,8,0) -> Yes | J3: =VLOOKUP(A3,'Medical Examinations'!A$1:J2338,10,0) -> Obesity | K3: =VLOOKUP(A3,'Medical Examinations'!A$1:K2337,11,0) -> Pre-Diabetes | L3: =VLOOKUP(A3,'Hospitalisation Details'!A$1:L2345,12,0) -> 8-Jun-1977 | M3: =VLOOKUP(A3,'Hospitalisation Details'!A$1:F2346,6,0) -> 62592.87 | N3: =VLOOKUP(A3,'Hospitalisation Details'!A$1:G2345,7,0) -> tier - 2 | O3: =VLOOKUP(A3,'Hospitalisation Details'!A$1:H2346,8,0) -> tier - 3 | P3: =VLOOKUP(A3,'Hospitalisation Details'!A$1:I2346,9,0) -> R1013 | Q3: =VLOOKUP(A3,'Hospitalisation Details'!A$1:M2346,13,0) -> 46
A4: Id3 | B4: =VLOOKUP(A4,'Customer Names'!A$1:D2339,4,0) -> Lu | C4: =VLOOKUP(A4,'Medical Examinations'!A$1:B2339,2,0) -> 34.485 | D4: =VLOOKUP(A4,'Medical Examinations'!A$1:C2340,3,0) -> 11.87 | E4: =VLOOKUP(A4,'Medical Examinations'!A$1:D2339,4,0) -> Yes | F4: =VLOOKUP(A4,'Medical Examinations'!A$1:E2339,5,0) -> NO | G4: =VLOOKUP(A4,'Medical Examinations'!A$1:F2339,6,0) -> NO | H4: =VLOOKUP(A4,'Medical Examinations'!A$1:G2339,7,0) -> 2 | I4: =VLOOKUP(A4,'Medical Examinations'!A$1:H2338,8,0) -> Yes | J4: =VLOOKUP(A4,'Medical Examinations'!A$1:J2339,10,0) -> Obesity | K4: =VLOOKUP(A4,'Medical Examinations'!A$1:K2338,11,0) -> Diabetes | L4: =VLOOKUP(A4,'Hospitalisation Details'!A$1:L2346,12,0) -> 11-Sep-1970 | M4: =VLOOKUP(A4,'Hospitalisation Details'!A$1:F2347,6,0) -> 60021.4 | N4: =VLOOKUP(A4,'Hospitalisation Details'!A$1:G2346,7,0) -> tier - 1 | O4: =VLOOKUP(A4,'Hospitalisation Details'!A$1:H2347,8,0) -> tier - 1 | P4: =VLOOKUP(A4,'Hospitalisation Details'!A$1:I2347,9,0) -> R1012 | Q4: =VLOOKUP(A4,'Hospitalisation Details'!A$1:M2347,13,0) -> 52
A5: Id4 | B5: =VLOOKUP(A5,'Customer Names'!A$1:D2340,4,0) -> Osborne | C5: =VLOOKUP(A5,'Medical Examinations'!A$1:B2340,2,0) -> 38.095 | D5: =VLOOKUP(A5,'Medical Examinations'!A$1:C2341,3,0) -> 6.05 | E5: =VLOOKUP(A5,'Medical Examinations'!A$1:D2340,4,0) -> NO | F5: =VLOOKUP(A5,'Medical Examinations'!A$1:E2340,5,0) -> NO | G5: =VLOOKUP(A5,'Medical Examinations'!A$1:F2340,6,0) -> NO | H5: =VLOOKUP(A5,'Medical Examinations'!A$1:G2340,7,0) -> 0 | I5: =VLOOKUP(A5,'Medical Examinations'!A$1:H2339,8,0) -> Yes | J5: =VLOOKUP(A5,'Medical Examinations'!A$1:J2340,10,0) -> Obesity | K5: =VLOOKUP(A5,'Medical Examinations'!A$1:K2339,11,0) -> Pre-Diabetes | L5: =VLOOKUP(A5,'Hospitalisation Details'!A$1:L2347,12,0) -> 6-Jun-1991 | M5: =VLOOKUP(A5,'Hospitalisation Details'!A$1:F2348,6,0) -> 58571.07 | N5: =VLOOKUP(A5,'Hospitalisation Details'!A$1:G2347,7,0) -> tier - 1 | O5: =VLOOKUP(A5,'Hospitalisation Details'!A$1:H2348,8,0) -> tier - 3 | P5: =VLOOKUP(A5,'Hospitalisation Details'!A$1:I2348,9,0) -> R1024 | Q5: =VLOOKUP(A5,'Hospitalisation Details'!A$1:M2348,13,0) -> 32
A6: Id5 | B6: =VLOOKUP(A6,'Customer Names'!A$1:D2341,4,0) -> Kadala | C6: =VLOOKUP(A6,'Medical Examinations'!A$1:B2341,2,0) -> 35.53 | D6: =VLOOKUP(A6,'Medical Examinations'!A$1:C2342,3,0) -> 5.45 | E6: =VLOOKUP(A6,'Medical Examinations'!A$1:D2341,4,0) -> NO | F6: =VLOOKUP(A6,'Medical Examinations'!A$1:E2341,5,0) -> NO | G6: =VLOOKUP(A6,'Medical Examinations'!A$1:F2341,6,0) -> NO | H6: =VLOOKUP(A6,'Medical Examinations'!A$1:G2341,7,0) -> 0 | I6: =VLOOKUP(A6,'Medical Examinations'!A$1:H2340,8,0) -> Yes | J6: =VLOOKUP(A6,'Medical Examinations'!A$1:J2341,10,0) -> Obesity | K6: =VLOOKUP(A6,'Medical Examinations'!A$1:K2340,11,0) -> Normal | L6: =VLOOKUP(A6,'Hospitalisation Details'!A$1:L2348,12,0) -> 19-Jun-1989 | M6: =VLOOKUP(A6,'Hospitalisation Details'!A$1:F2349,6,0) -> 55135.4 | N6: =VLOOKUP(A6,'Hospitalisation Details'!A$1:G2348,7,0) -> tier - 1 | O6: =VLOOKUP(A6,'Hospitalisation Details'!A$1:H2349,8,0) -> tier - 2 | P6: =VLOOKUP(A6,'Hospitalisation Details'!A$1:I2349,9,0) -> R1012 | Q6: =VLOOKUP(A6,'Hospitalisation Details'!A$1:M2349,13,0) -> 33
A7: Id6 | B7: =VLOOKUP(A7,'Customer Names'!A$1:D2342,4,0) -> Baker | C7: =VLOOKUP(A7,'Medical Examinations'!A$1:B2342,2,0) -> 32.8 | D7: =VLOOKUP(A7,'Medical Examinations'!A$1:C2343,3,0) -> 6.59 | E7: =VLOOKUP(A7,'Medical Examinations'!A$1:D2342,4,0) -> NO | F7: =VLOOKUP(A7,'Medical Examinations'!A$1:E2342,5,0) -> NO | G7: =VLOOKUP(A7,'Medical Examinations'!A$1:F2342,6,0) -> NO | H7: =VLOOKUP(A7,'Medical Examinations'!A$1:G2342,7,0) -> 0 | I7: =VLOOKUP(A7,'Medical Examinations'!A$1:H2341,8,0) -> Yes | J7: =VLOOKUP(A7,'Medical Examinations'!A$1:J2342,10,0) -> Obesity | K7: =VLOOKUP(A7,'Medical Examinations'!A$1:K2341,11,0) -> Diabetes | L7: =VLOOKUP(A7,'Hospitalisation Details'!A$1:L2349,12,0) -> 4-Aug-1962 | M7: =VLOOKUP(A7,'Hospitalisation Details'!A$1:F2350,6,0) -> 52590.83 | N7: =VLOOKUP(A7,'Hospitalisation Details'!A$1:G2349,7,0) -> tier - 1 | O7: =VLOOKUP(A7,'Hospitalisation Details'!A$1:H2350,8,0) -> tier - 3 | P7: =VLOOKUP(A7,'Hospitalisation Details'!A$1:I2350,9,0) -> R1011 | Q7: =VLOOKUP(A7,'Hospitalisation Details'!A$1:M2350,13,0) -> 60
A8: Id7 | B8: =VLOOKUP(A8,'Customer Names'!A$1:D2343,4,0) -> Macpherson | C8: =VLOOKUP(A8,'Medical Examinations'!A$1:B2343,2,0) -> 36.4 | D8: =VLOOKUP(A8,'Medical Examinations'!A$1:C2344,3,0) -> 6.07 | E8: =VLOOKUP(A8,'Medical Examinations'!A$1:D2343,4,0) -> NO | F8: =VLOOKUP(A8,'Medical Examinations'!A$1:E2343,5,0) -> NO | G8: =VLOOKUP(A8,'Medical Examinations'!A$1:F2343,6,0) -> NO | H8: =VLOOKUP(A8,'Medical Examinations'!A$1:G2343,7,0) -> 0 | I8: =VLOOKUP(A8,'Medical Examinations'!A$1:H2342,8,0) -> Yes | J8: =VLOOKUP(A8,'Medical Examinations'!A$1:J2343,10,0) -> Obesity | K8: =VLOOKUP(A8,'Medical Examinations'!A$1:K2342,11,0) -> Pre-Diabetes | L8: =VLOOKUP(A8,'Hospitalisation Details'!A$1:L2350,12,0) -> 27-Oct-1994 | M8: =VLOOKUP(A8,'Hospitalisation Details'!A$1:F2351,6,0) -> 51194.56 | N8: =VLOOKUP(A8,'Hospitalisation Details'!A$1:G2350,7,0) -> tier - 1 | O8: =VLOOKUP(A8,'Hospitalisation Details'!A$1:H2351,8,0) -> tier - 3 | P8: =VLOOKUP(A8,'Hospitalisation Details'!A$1:I2351,9,0) -> R1011 | Q8: =VLOOKUP(A8,'Hospitalisation Details'!A$1:M2351,13,0) -> 28
A9: Id8 | B9: =VLOOKUP(A9,'Customer Names'!A$1:D2344,4,0) -> Hallman | C9: =VLOOKUP(A9,'Medical Examinations'!A$1:B2344,2,0) -> 36.96 | D9: =VLOOKUP(A9,'Medical Examinations'!A$1:C2345,3,0) -> 7.93 | E9: =VLOOKUP(A9,'Medical Examinations'!A$1:D2344,4,0) -> NO | F9: =VLOOKUP(A9,'Medical Examinations'!A$1:E2344,5,0) -> NO | G9: =VLOOKUP(A9,'Medical Examinations'!A$1:F2344,6,0) -> NO | H9: =VLOOKUP(A9,'Medical Examinations'!A$1:G2344,7,0) -> 3 | I9: =VLOOKUP(A9,'Medical Examinations'!A$1:H2343,8,0) -> Yes | J9: =VLOOKUP(A9,'Medical Examinations'!A$1:J2344,10,0) -> Obesity | K9: =VLOOKUP(A9,'Medical Examinations'!A$1:K2343,11,0) -> Diabetes | L9: =VLOOKUP(A9,'Hospitalisation Details'!A$1:L2351,12,0) -> 27-Jun-1958 | M9: =VLOOKUP(A9,'Hospitalisation Details'!A$1:F2352,6,0) -> 49577.66 | N9: =VLOOKUP(A9,'Hospitalisation Details'!A$1:G2351,7,0) -> tier - 2 | O9: =VLOOKUP(A9,'Hospitalisation Details'!A$1:H2352,8,0) -> tier - 2 | P9: =VLOOKUP(A9,'Hospitalisation Details'!A$1:I2352,9,0) -> R1013 | Q9: =VLOOKUP(A9,'Hospitalisation Details'!A$1:M2352,13,0) -> 64
A10: Id9 | B10: =VLOOKUP(A10,'Customer Names'!A$1:D2345,4,0) -> Moran | C10: =VLOOKUP(A10,'Medical Examinations'!A$1:B2345,2,0) -> 41.14 | D10: =VLOOKUP(A10,'Medical Examinations'!A$1:C2346,3,0) -> 9.58 | E10: =VLOOKUP(A10,'Medical Examinations'!A$1:D2345,4,0) -> Yes | F10: =VLOOKUP(A10,'Medical Examinations'!A$1:E2345,5,0) -> NO | G10: =VLOOKUP(A10,'Medical Examinations'!A$1:F2345,6,0) -> Yes | H10: =VLOOKUP(A10,'Medical Examinations'!A$1:G2345,7,0) -> 1 | I10: =VLOOKUP(A10,'Medical Examinations'!A$1:H2344,8,0) -> Yes | J10: =VLOOKUP(A10,'Medical Examinations'!A$1:J2345,10,0) -> Obesity | K10: =VLOOKUP(A10,'Medical Examinations'!A$1:K2344,11,0) -> Diabetes | L10: =VLOOKUP(A10,'Hospitalisation Details'!A$1:L2352,12,0) -> 4-Sep-1963 | M10: =VLOOKUP(A10,'Hospitalisation Details'!A$1:F2353,6,0) -> 48970.25 | N10: =VLOOKUP(A10,'Hospitalisation Details'!A$1:G2352,7,0) -> tier - 1 | O10: =VLOOKUP(A10,'Hospitalisation Details'!A$1:H2353,8,0) -> tier - 2 | P10: =VLOOKUP(A10,'Hospitalisation Details'!A$1:I2353,9,0) -> R1013 | Q10: =VLOOKUP(A10,'Hospitalisation Details'!A$1:M2353,13,0) -> 59
A11: Id10 | B11: =VLOOKUP(A11,'Customer Names'!A$1:D2346,4,0) -> Benner | C11: =VLOOKUP(A11,'Medical Examinations'!A$1:B2346,2,0) -> 38.06 | D11: =VLOOKUP(A11,'Medical Examinations'!A$1:C2347,3,0) -> 10.79 | E11: =VLOOKUP(A11,'Medical Examinations'!A$1:D2346,4,0) -> NO | F11: =VLOOKUP(A11,'Medical Examinations'!A$1:E2346,5,0) -> NO | G11: =VLOOKUP(A11,'Medical Examinations'!A$1:F2346,6,0) -> NO | H11: =VLOOKUP(A11,'Medical Examinations'!A$1:G2346,7,0) -> 0 | I11: =VLOOKUP(A11,'Medical Examinations'!A$1:H2345,8,0) -> Yes | J11: =VLOOKUP(A11,'Medical Examinations'!A$1:J2346,10,0) -> Obesity | K11: =VLOOKUP(A11,'Medical Examinations'!A$1:K2345,11,0) -> Diabetes | L11: =VLOOKUP(A11,'Hospitalisation Details'!A$1:L2353,12,0) -> 29-Dec-1978 | M11: =VLOOKUP(A11,'Hospitalisation Details'!A$1:F2354,6,0) -> 48885.14 | N11: =VLOOKUP(A11,'Hospitalisation Details'!A$1:G2353,7,0) -> tier - 1 | O11: =VLOOKUP(A11,'Hospitalisation Details'!A$1:H2354,8,0) -> tier - 2 | P11: =VLOOKUP(A11,'Hospitalisation Details'!A$1:I2354,9,0) -> R1013 | Q11: =VLOOKUP(A11,'Hospitalisation Details'!A$1:M2354,13,0) -> 44
A12: Id11 | B12: =VLOOKUP(A12,'Customer Names'!A$1:D2347,4,0) -> Fierro Vargas | C12: =VLOOKUP(A12,'Medical Examinations'!A$1:B2347,2,0) -> 37.7 | D12: =VLOOKUP(A12,'Medical Examinations'!A$1:C2348,3,0) -> 5.96 | E12: =VLOOKUP(A12,'Medical Examinations'!A$1:D2347,4,0) -> Yes | F12: =VLOOKUP(A12,'Medical Examinations'!A$1:E2347,5,0) -> NO | G12: =VLOOKUP(A12,'Medical Examinations'!A$1:F2347,6,0) -> NO | H12: =VLOOKUP(A12,'Medical Examinations'!A$1:G2347,7,0) -> 2 | I12: =VLOOKUP(A12,'Medical Examinations'!A$1:H2346,8,0) -> Yes | J12: =VLOOKUP(A12,'Medical Examinations'!A$1:J2347,10,0) -> Obesity | K12: =VLOOKUP(A12,'Medical Examinations'!A$1:K2346,11,0) -> Pre-Diabetes | L12: =VLOOKUP(A12,'Hospitalisation Details'!A$1:L2354,12,0) -> 22-Jul-1959 | M12: =VLOOKUP(A12,'Hospitalisation Details'!A$1:F2355,6,0) -> 48824.45 | N12: =VLOOKUP(A12,'Hospitalisation Details'!A$1:G2354,7,0) -> tier - 2 | O12: =VLOOKUP(A12,'Hospitalisation Details'!A$1:H2355,8,0) -> tier - 1 | P12: =VLOOKUP(A12,'Hospitalisation Details'!A$1:I2355,9,0) -> R1011 | Q12: =VLOOKUP(A12,'Hospitalisation Details'!A$1:M2355,13,0) -> 63
A13: Id12 | B13: =VLOOKUP(A13,'Customer Names'!A$1:D2348,4,0) -> Franz | C13: =VLOOKUP(A13,'Medical Examinations'!A$1:B2348,2,0) -> 42.13 | D13: =VLOOKUP(A13,'Medical Examinations'!A$1:C2349,3,0) -> 11.9 | E13: =VLOOKUP(A13,'Medical Examinations'!A$1:D2348,4,0) -> NO | F13: =VLOOKUP(A13,'Medical Examinations'!A$1:E2348,5,0) -> NO | G13: =VLOOKUP(A13,'Medical Examinations'!A$1:F2348,6,0) -> NO | H13: =VLOOKUP(A13,'Medical Examinations'!A$1:G2348,7,0) -> 0 | I13: =VLOOKUP(A13,'Medical Examinations'!A$1:H2347,8,0) -> Yes | J13: =VLOOKUP(A13,'Medical Examinations'!A$1:J2348,10,0) -> Obesity | K13: =VLOOKUP(A13,'Medical Examinations'!A$1:K2347,11,0) -> Diabetes | L13: =VLOOKUP(A13,'Hospitalisation Details'!A$1:L2355,12,0) -> 27-Oct-1965 | M13: =VLOOKUP(A13,'Hospitalisation Details'!A$1:F2356,6,0) -> 48675.52 | N13: =VLOOKUP(A13,'Hospitalisation Details'!A$1:G2355,7,0) -> tier - 1 | O13: =VLOOKUP(A13,'Hospitalisation Details'!A$1:H2356,8,0) -> tier - 2 | P13: =VLOOKUP(A13,'Hospitalisation Details'!A$1:I2356,9,0) -> R1013 | Q13: =VLOOKUP(A13,'Hospitalisation Details'!A$1:M2356,13,0) -> 57
... A546: Id545 | B546: =VLOOKUP(A546,'Customer Names'!A$1:D2881,4,0) -> Shigezumi | C546: =VLOOKUP(A546,'Medical Examinations'!A$1:B2881,2,0) -> 44.2 | D546: =VLOOKUP(A546,'Medical Examinations'!A$1:C2882,3,0) -> 11.34 | E546: =VLOOKUP(A546,'Medical Examinations'!A$1:D2881,4,0) -> Yes | F546: =VLOOKUP(A546,'Medical Examinations'!A$1:E2881,5,0) -> NO | G546: =VLOOKUP(A546,'Medical Examinations'!A$1:F2881,6,0) -> Yes | H546: =VLOOKUP(A546,'Medical Examinations'!A$1:G2881,7,0) -> 1 | I546: =VLOOKUP(A546,'Medical Examinations'!A$1:H2880,8,0) -> NO | J546: =VLOOKUP(A546,'Medical Examinations'!A$1:J2881,10,0) -> Over Weight | K546: =VLOOKUP(A546,'Medical Examinations'!A$1:K2880,11,0) -> Diabetes | L546: =VLOOKUP(A546,'Hospitalisation Details'!A$1:L2888,12,0) -> 4-Jul-1963 | M546: =VLOOKUP(A546,'Hospitalisation Details'!A$1:F2889,6,0) -> 18208.34 | N546: =VLOOKUP(A546,'Hospitalisation Details'!A$1:G2888,7,0) -> tier - 1 | O546: =VLOOKUP(A546,'Hospitalisation Details'!A$1:H2889,8,0) -> tier - 2 | P546: =VLOOKUP(A546,'Hospitalisation Details'!A$1:I2889,9,0) -> R1026 | Q546: =VLOOKUP(A546,'Hospitalisation Details'!A$1:M2889,13,0) -> 59
A547: Id546 | B547: =VLOOKUP(A547,'Customer Names'!A$1:D2882,4,0) -> Meineke | C547: =VLOOKUP(A547,'Medical Examinations'!A$1:B2882,2,0) -> 29.735 | D547: =VLOOKUP(A547,'Medical Examinations'!A$1:C2883,3,0) -> 4.53 | E547: =VLOOKUP(A547,'Medical Examinations'!A$1:D2882,4,0) -> NO | F547: =VLOOKUP(A547,'Medical Examinations'!A$1:E2882,5,0) -> NO | G547: =VLOOKUP(A547,'Medical Examinations'!A$1:F2882,6,0) -> Yes | H547: =VLOOKUP(A547,'Medical Examinations'!A$1:G2882,7,0) -> 1 | I547: =VLOOKUP(A547,'Medical Examinations'!A$1:H2881,8,0) -> NO | J547: =VLOOKUP(A547,'Medical Examinations'!A$1:J2882,10,0) -> Over Weight | K547: =VLOOKUP(A547,'Medical Examinations'!A$1:K2881,11,0) -> Normal | L547: =VLOOKUP(A547,'Hospitalisation Details'!A$1:L2889,12,0) -> 12-Jul-1993 | M547: =VLOOKUP(A547,'Hospitalisation Details'!A$1:F2890,6,0) -> 18157.88 | N547: =VLOOKUP(A547,'Hospitalisation Details'!A$1:G2889,7,0) -> tier - 1 | O547: =VLOOKUP(A547,'Hospitalisation Details'!A$1:H2890,8,0) -> tier - 1 | P547: UNKNOWN | Q547: =VLOOKUP(A547,'Hospitalisation Details'!A$1:M2890,13,0) -> 29
A548: Id547 | B548: =VLOOKUP(A548,'Customer Names'!A$1:D2883,4,0) -> Ludington | C548: =VLOOKUP(A548,'Medical Examinations'!A$1:B2883,2,0) -> 28.31 | D548: =VLOOKUP(A548,'Medical Examinations'!A$1:C2884,3,0) -> 6.35 | E548: =VLOOKUP(A548,'Medical Examinations'!A$1:D2883,4,0) -> NO | F548: =VLOOKUP(A548,'Medical Examinations'!A$1:E2883,5,0) -> NO | G548: =VLOOKUP(A548,'Medical Examinations'!A$1:F2883,6,0) -> NO | H548: =VLOOKUP(A548,'Medical Examinations'!A$1:G2883,7,0) -> 0 | I548: =VLOOKUP(A548,'Medical Examinations'!A$1:H2882,8,0) -> Yes | J548: =VLOOKUP(A548,'Medical Examinations'!A$1:J2883,10,0) -> Obesity | K548: =VLOOKUP(A548,'Medical Examinations'!A$1:K2882,11,0) -> Pre-Diabetes | L548: =VLOOKUP(A548,'Hospitalisation Details'!A$1:L2890,12,0) -> 24-Oct-1999 | M548: =VLOOKUP(A548,'Hospitalisation Details'!A$1:F2891,6,0) -> 18033.97 | N548: =VLOOKUP(A548,'Hospitalisation Details'!A$1:G2890,7,0) -> tier - 1 | O548: =VLOOKUP(A548,'Hospitalisation Details'!A$1:H2891,8,0) -> tier - 1 | P548: =VLOOKUP(A548,'Hospitalisation Details'!A$1:I2891,9,0) -> R1012 | Q548: =VLOOKUP(A548,'Hospitalisation Details'!A$1:M2891,13,0) -> 23
A549: Id548 | B549: =VLOOKUP(A549,'Customer Names'!A$1:D2884,4,0) -> Perrich | C549: =VLOOKUP(A549,'Medical Examinations'!A$1:B2884,2,0) -> 46.62 | D549: =VLOOKUP(A549,'Medical Examinations'!A$1:C2885,3,0) -> 8.51 | E549: =VLOOKUP(A549,'Medical Examinations'!A$1:D2884,4,0) -> NO | F549: =VLOOKUP(A549,'Medical Examinations'!A$1:E2884,5,0) -> NO | G549: =VLOOKUP(A549,'Medical Examinations'!A$1:F2884,6,0) -> NO | H549: =VLOOKUP(A549,'Medical Examinations'!A$1:G2884,7,0) -> 0 | I549: =VLOOKUP(A549,'Medical Examinations'!A$1:H2883,8,0) -> NO | J549: =VLOOKUP(A549,'Medical Examinations'!A$1:J2884,10,0) -> Obesity | K549: =VLOOKUP(A549,'Medical Examinations'!A$1:K2883,11,0) -> Diabetes | L549: =VLOOKUP(A549,'Hospitalisation Details'!A$1:L2891,12,0) -> 17-Oct-1965 | M549: =VLOOKUP(A549,'Hospitalisation Details'!A$1:F2892,6,0) -> 18031.19 | N549: =VLOOKUP(A549,'Hospitalisation Details'!A$1:G2891,7,0) -> tier - 1 | O549: =VLOOKUP(A549,'Hospitalisation Details'!A$1:H2892,8,0) -> tier - 2 | P549: =VLOOKUP(A549,'Hospitalisation Details'!A$1:I2892,9,0) -> R1012 | Q549: =VLOOKUP(A549,'Hospitalisation Details'!A$1:M2892,13,0) -> 57
A550: Id549 | B550: =VLOOKUP(A550,'Customer Names'!A$1:D2885,4,0) -> Cervantes | C550: =VLOOKUP(A550,'Medical Examinations'!A$1:B2885,2,0) -> 51.75 | D550: =VLOOKUP(A550,'Medical Examinations'!A$1:C2886,3,0) -> 8.59 | E550: =VLOOKUP(A550,'Medical Examinations'!A$1:D2885,4,0) -> Yes | F550: =VLOOKUP(A550,'Medical Examinations'!A$1:E2885,5,0) -> NO | G550: =VLOOKUP(A550,'Medical Examinations'!A$1:F2885,6,0) -> NO | H550: =VLOOKUP(A550,'Medical Examinations'!A$1:G2885,7,0) -> 1 | I550: =VLOOKUP(A550,'Medical Examinations'!A$1:H2884,8,0) -> NO | J550: =VLOOKUP(A550,'Medical Examinations'!A$1:J2885,10,0) -> Over Weight | K550: =VLOOKUP(A550,'Medical Examinations'!A$1:K2884,11,0) -> Diabetes | L550: =VLOOKUP(A550,'Hospitalisation Details'!A$1:L2892,12,0) -> 27-Jun-1975 | M550: =VLOOKUP(A550,'Hospitalisation Details'!A$1:F2893,6,0) -> 18031.16 | N550: =VLOOKUP(A550,'Hospitalisation Details'!A$1:G2892,7,0) -> tier - 1 | O550: =VLOOKUP(A550,'Hospitalisation Details'!A$1:H2893,8,0) -> tier - 3 | P550: =VLOOKUP(A550,'Hospitalisation Details'!A$1:I2893,9,0) -> R1023 | Q550: =VLOOKUP(A550,'Hospitalisation Details'!A$1:M2893,13,0) -> 47
A551: Id550 | B551: =VLOOKUP(A551,'Customer Names'!A$1:D2886,4,0) -> Andrews | C551: =VLOOKUP(A551,'Medical Examinations'!A$1:B2886,2,0) -> 25.7 | D551: =VLOOKUP(A551,'Medical Examinations'!A$1:C2887,3,0) -> 4.13 | E551: =VLOOKUP(A551,'Medical Examinations'!A$1:D2886,4,0) -> Yes | F551: =VLOOKUP(A551,'Medical Examinations'!A$1:E2886,5,0) -> NO | G551: =VLOOKUP(A551,'Medical Examinations'!A$1:F2886,6,0) -> NO | H551: =VLOOKUP(A551,'Medical Examinations'!A$1:G2886,7,0) -> 0 | I551: =VLOOKUP(A551,'Medical Examinations'!A$1:H2885,8,0) -> Yes | J551: =VLOOKUP(A551,'Medical Examinations'!A$1:J2886,10,0) -> Obesity | K551: =VLOOKUP(A551,'Medical Examinations'!A$1:K2885,11,0) -> Normal | L551: =VLOOKUP(A551,'Hospitalisation Details'!A$1:L2893,12,0) -> 28-Sep-2001 | M551: =VLOOKUP(A551,'Hospitalisation Details'!A$1:F2894,6,0) -> 17942.11 | N551: =VLOOKUP(A551,'Hospitalisation Details'!A$1:G2893,7,0) -> tier - 1 | O551: =VLOOKUP(A551,'Hospitalisation Details'!A$1:H2894,8,0) -> tier - 2 | P551: =VLOOKUP(A551,'Hospitalisation Details'!A$1:I2894,9,0) -> R1011 | Q551: =VLOOKUP(A551,'Hospitalisation Details'!A$1:M2894,13,0) -> 21
A552: Id551 | B552: =VLOOKUP(A552,'Customer Names'!A$1:D2887,4,0) -> Ruvalcaba | C552: =VLOOKUP(A552,'Medical Examinations'!A$1:B2887,2,0) -> 31.79 | D552: =VLOOKUP(A552,'Medical Examinations'!A$1:C2888,3,0) -> 4.55 | E552: =VLOOKUP(A552,'Medical Examinations'!A$1:D2887,4,0) -> NO | F552: =VLOOKUP(A552,'Medical Examinations'!A$1:E2887,5,0) -> NO | G552: =VLOOKUP(A552,'Medical Examinations'!A$1:F2887,6,0) -> NO | H552: =VLOOKUP(A552,'Medical Examinations'!A$1:G2887,7,0) -> 0 | I552: =VLOOKUP(A552,'Medical Examinations'!A$1:H2886,8,0) -> NO | J552: =VLOOKUP(A552,'Medical Examinations'!A$1:J2887,10,0) -> NormalWeight | K552: =VLOOKUP(A552,'Medical Examinations'!A$1:K2886,11,0) -> Normal | L552: =VLOOKUP(A552,'Hospitalisation Details'!A$1:L2894,12,0) -> 17-Oct-1977 | M552: =VLOOKUP(A552,'Hospitalisation Details'!A$1:F2895,6,0) -> 17929.3 | N552: =VLOOKUP(A552,'Hospitalisation Details'!A$1:G2894,7,0) -> tier - 1 | O552: =VLOOKUP(A552,'Hospitalisation Details'!A$1:H2895,8,0) -> tier - 2 | P552: =VLOOKUP(A552,'Hospitalisation Details'!A$1:I2895,9,0) -> R1013 | Q552: =VLOOKUP(A552,'Hospitalisation Details'!A$1:M2895,13,0) -> 45
A553: Id552 | B553: =VLOOKUP(A553,'Customer Names'!A$1:D2888,4,0) -> King | C553: =VLOOKUP(A553,'Medical Examinations'!A$1:B2888,2,0) -> 24.795 | D553: =VLOOKUP(A553,'Medical Examinations'!A$1:C2889,3,0) -> 4.52 | E553: =VLOOKUP(A553,'Medical Examinations'!A$1:D2888,4,0) -> NO | F553: =VLOOKUP(A553,'Medical Examinations'!A$1:E2888,5,0) -> NO | G553: =VLOOKUP(A553,'Medical Examinations'!A$1:F2888,6,0) -> NO | H553: =VLOOKUP(A553,'Medical Examinations'!A$1:G2888,7,0) -> 0 | I553: =VLOOKUP(A553,'Medical Examinations'!A$1:H2887,8,0) -> Yes | J553: =VLOOKUP(A553,'Medical Examinations'!A$1:J2888,10,0) -> Obesity | K553: =VLOOKUP(A553,'Medical Examinations'!A$1:K2887,11,0) -> Normal | L553: =VLOOKUP(A553,'Hospitalisation Details'!A$1:L2895,12,0) -> 4-Dec-1989 | M553: =VLOOKUP(A553,'Hospitalisation Details'!A$1:F2896,6,0) -> 17904.53 | N553: =VLOOKUP(A553,'Hospitalisation Details'!A$1:G2895,7,0) -> tier - 1 | O553: =VLOOKUP(A553,'Hospitalisation Details'!A$1:H2896,8,0) -> tier - 2 | P553: =VLOOKUP(A553,'Hospitalisation Details'!A$1:I2896,9,0) -> R1017 | Q553: =VLOOKUP(A553,'Hospitalisation Details'!A$1:M2896,13,0) -> 33
A554: Id553 | B554: =VLOOKUP(A554,'Customer Names'!A$1:D2889,4,0) -> Stone | C554: =VLOOKUP(A554,'Medical Examinations'!A$1:B2889,2,0) -> 53.98 | D554: =VLOOKUP(A554,'Medical Examinations'!A$1:C2890,3,0) -> 5.07 | E554: =VLOOKUP(A554,'Medical Examinations'!A$1:D2889,4,0) -> NO | F554: =VLOOKUP(A554,'Medical Examinations'!A$1:E2889,5,0) -> NO | G554: =VLOOKUP(A554,'Medical Examinations'!A$1:F2889,6,0) -> Yes | H554: =VLOOKUP(A554,'Medical Examinations'!A$1:G2889,7,0) -> 1 | I554: =VLOOKUP(A554,'Medical Examinations'!A$1:H2888,8,0) -> NO | J554: =VLOOKUP(A554,'Medical Examinations'!A$1:J2889,10,0) -> Obesity | K554: =VLOOKUP(A554,'Medical Examinations'!A$1:K2888,11,0) -> Normal | L554: =VLOOKUP(A554,'Hospitalisation Details'!A$1:L2896,12,0) -> 12-Nov-1979 | M554: =VLOOKUP(A554,'Hospitalisation Details'!A$1:F2897,6,0) -> 17882.67 | N554: =VLOOKUP(A554,'Hospitalisation Details'!A$1:G2896,7,0) -> tier - 1 | O554: =VLOOKUP(A554,'Hospitalisation Details'!A$1:H2897,8,0) -> tier - 3 | P554: =VLOOKUP(A554,'Hospitalisation Details'!A$1:I2897,9,0) -> R1012 | Q554: =VLOOKUP(A554,'Hospitalisation Details'!A$1:M2897,13,0) -> 43
A555: Id554 | B555: =VLOOKUP(A555,'Customer Names'!A$1:D2890,4,0) -> Campbell | C555: =VLOOKUP(A555,'Medical Examinations'!A$1:B2890,2,0) -> 41.325 | D555: =VLOOKUP(A555,'Medical Examinations'!A$1:C2891,3,0) -> 4.04 | E555: =VLOOKUP(A555,'Medical Examinations'!A$1:D2890,4,0) -> Yes | F555: =VLOOKUP(A555,'Medical Examinations'!A$1:E2890,5,0) -> NO | G555: =VLOOKUP(A555,'Medical Examinations'!A$1:F2890,6,0) -> Yes | H555: =VLOOKUP(A555,'Medical Examinations'!A$1:G2890,7,0) -> 1 | I555: =VLOOKUP(A555,'Medical Examinations'!A$1:H2889,8,0) -> NO | J555: =VLOOKUP(A555,'Medical Examinations'!A$1:J2890,10,0) -> Obesity | K555: =VLOOKUP(A555,'Medical Examinations'!A$1:K2889,11,0) -> Normal | L555: =VLOOKUP(A555,'Hospitalisation Details'!A$1:L2897,12,0) -> 26-Aug-1997 | M555: =VLOOKUP(A555,'Hospitalisation Details'!A$1:F2898,6,0) -> 17878.9 | N555: =VLOOKUP(A555,'Hospitalisation Details'!A$1:G2897,7,0) -> tier - 1 | O555: =VLOOKUP(A555,'Hospitalisation Details'!A$1:H2898,8,0) -> tier - 2 | P555: =VLOOKUP(A555,'Hospitalisation Details'!A$1:I2898,9,0) -> R1024 | Q555: =VLOOKUP(A555,'Hospitalisation Details'!A$1:M2898,13,0) -> 25
A556: Id555 | B556: =VLOOKUP(A556,'Customer Names'!A$1:D2891,4,0) -> Asher | C556: =VLOOKUP(A556,'Medical Examinations'!A$1:B2891,2,0) -> 51.65 | D556: =VLOOKUP(A556,'Medical Examinations'!A$1:C2892,3,0) -> 5.3 | E556: =VLOOKUP(A556,'Medical Examinations'!A$1:D2891,4,0) -> Yes | F556: =VLOOKUP(A556,'Medical Examinations'!A$1:E2891,5,0) -> NO | G556: =VLOOKUP(A556,'Medical Examinations'!A$1:F2891,6,0) -> NO | H556: =VLOOKUP(A556,'Medical Examinations'!A$1:G2891,7,0) -> 0 | I556: =VLOOKUP(A556,'Medical Examinations'!A$1:H2890,8,0) -> NO | J556: =VLOOKUP(A556,'Medical Examinations'!A$1:J2891,10,0) -> Obesity | K556: =VLOOKUP(A556,'Medical Examinations'!A$1:K2890,11,0) -> Normal | L556: =VLOOKUP(A556,'Hospitalisation Details'!A$1:L2898,12,0) -> 12-Dec-1976 | M556: =VLOOKUP(A556,'Hospitalisation Details'!A$1:F2899,6,0) -> 17862.92 | N556: =VLOOKUP(A556,'Hospitalisation Details'!A$1:G2898,7,0) -> tier - 1 | O556: =VLOOKUP(A556,'Hospitalisation Details'!A$1:H2899,8,0) -> tier - 2 | P556: =VLOOKUP(A556,'Hospitalisation Details'!A$1:I2899,9,0) -> R1012 | Q556: =VLOOKUP(A556,'Hospitalisation Details'!A$1:M2899,13,0) -> 46
A557: Id556 | B557: =VLOOKUP(A557,'Customer Names'!A$1:D2892,4,0) -> Mazzotta | C557: =VLOOKUP(A557,'Medical Examinations'!A$1:B2892,2,0) -> 44.52 | D557: =VLOOKUP(A557,'Medical Examinations'!A$1:C2893,3,0) -> 8.64 | E557: =VLOOKUP(A557,'Medical Examinations'!A$1:D2892,4,0) -> Yes | F557: =VLOOKUP(A557,'Medical Examinations'!A$1:E2892,5,0) -> NO | G557: =VLOOKUP(A557,'Medical Examinations'!A$1:F2892,6,0) -> Yes | H557: =VLOOKUP(A557,'Medical Examinations'!A$1:G2892,7,0) -> 1 | I557: =VLOOKUP(A557,'Medical Examinations'!A$1:H2891,8,0) -> NO | J557: =VLOOKUP(A557,'Medical Examinations'!A$1:J2892,10,0) -> Obesity | K557: =VLOOKUP(A557,'Medical Examinations'!A$1:K2891,11,0) -> Diabetes | L557: =VLOOKUP(A557,'Hospitalisation Details'!A$1:L2899,12,0) -> 8-Dec-1963 | M557: =VLOOKUP(A557,'Hospitalisation Details'!A$1:F2900,6,0) -> 17832.6 | N557: =VLOOKUP(A557,'Hospitalisation Details'!A$1:G2899,7,0) -> tier - 1 | O557: =VLOOKUP(A557,'Hospitalisation Details'!A$1:H2900,8,0) -> tier - 2 | P557: =VLOOKUP(A557,'Hospitalisation Details'!A$1:I2900,9,0) -> R1012 | Q557: =VLOOKUP(A557,'Hospitalisation Details'!A$1:M2900,13,0) -> 59
A558: Id557 | B558: =VLOOKUP(A558,'Customer Names'!A$1:D2893,4,0) -> Huttl | C558: =VLOOKUP(A558,'Medical Examinations'!A$1:B2893,2,0) -> 53.29 | D558: =VLOOKUP(A558,'Medical Examinations'!A$1:C2894,3,0) -> 4.03 | E558: =VLOOKUP(A558,'Medical Examinations'!A$1:D2893,4,0) -> NO | F558: =VLOOKUP(A558,'Medical Examinations'!A$1:E2893,5,0) -> NO | G558: =VLOOKUP(A558,'Medical Examinations'!A$1:F2893,6,0) -> Yes | H558: =VLOOKUP(A558,'Medical Examinations'!A$1:G2893,7,0) -> 1 | I558: =VLOOKUP(A558,'Medical Examinations'!A$1:H2892,8,0) -> NO | J558: =VLOOKUP(A558,'Medical Examinations'!A$1:J2893,10,0) -> Obesity | K558: =VLOOKUP(A558,'Medical Examinations'!A$1:K2892,11,0) -> Normal | L558: =VLOOKUP(A558,'Hospitalisation Details'!A$1:L2900,12,0) -> 10-Oct-1979 | M558: =VLOOKUP(A558,'Hospitalisation Details'!A$1:F2901,6,0) -> 17779.94 | N558: =VLOOKUP(A558,'Hospitalisation Details'!A$1:G2900,7,0) -> tier - 1 | O558: =VLOOKUP(A558,'Hospitalisation Details'!A$1:H2901,8,0) -> tier - 2 | P558: =VLOOKUP(A558,'Hospitalisation Details'!A$1:I2901,9,0) -> R1012 | Q558: =VLOOKUP(A558,'Hospitalisation Details'!A$1:M2901,13,0) -> 43
A559: Id558 | B559: =VLOOKUP(A559,'Customer Names'!A$1:D2894,4,0) -> Ferron | C559: =VLOOKUP(A559,'Medical Examinations'!A$1:B2894,2,0) -> 46.63 | D559: =VLOOKUP(A559,'Medical Examinations'!A$1:C2895,3,0) -> 4.26 | E559: =VLOOKUP(A559,'Medical Examinations'!A$1:D2894,4,0) -> Yes | F559: =VLOOKUP(A559,'Medical Examinations'!A$1:E2894,5,0) -> NO | G559: =VLOOKUP(A559,'Medical Examinations'!A$1:F2894,6,0) -> NO | H559: =VLOOKUP(A559,'Medical Examinations'!A$1:G2894,7,0) -> 2 | I559: =VLOOKUP(A559,'Medical Examinations'!A$1:H2893,8,0) -> NO | J559: =VLOOKUP(A559,'Medical Examinations'!A$1:J2894,10,0) -> Over Weight | K559: =VLOOKUP(A559,'Medical Examinations'!A$1:K2893,11,0) -> Normal | L559: =VLOOKUP(A559,'Hospitalisation Details'!A$1:L2901,12,0) -> 21-Jun-1966 | M559: =VLOOKUP(A559,'Hospitalisation Details'!A$1:F2902,6,0) -> 17777.73 | N559: =VLOOKUP(A559,'Hospitalisation Details'!A$1:G2901,7,0) -> tier - 1 | O559: =VLOOKUP(A559,'Hospitalisation Details'!A$1:H2902,8,0) -> tier - 3 | P559: =VLOOKUP(A559,'Hospitalisation Details'!A$1:I2902,9,0) -> R1012 | Q559: =VLOOKUP(A559,'Hospitalisation Details'!A$1:M2902,13,0) -> 56
... A2174: Id2173 | B2174: =VLOOKUP(A2174,'Customer Names'!A$1:D4509,4,0) -> Lozier | C2174: =VLOOKUP(A2174,'Medical Examinations'!A$1:B4509,2,0) -> 29.735 | D2174: =VLOOKUP(A2174,'Medical Examinations'!A$1:C4510,3,0) -> 11.92 | E2174: =VLOOKUP(A2174,'Medical Examinations'!A$1:D4509,4,0) -> NO | F2174: =VLOOKUP(A2174,'Medical Examinations'!A$1:E4509,5,0) -> NO | G2174: =VLOOKUP(A2174,'Medical Examinations'!A$1:F4509,6,0) -> NO | H2174: =VLOOKUP(A2174,'Medical Examinations'!A$1:G4509,7,0) -> 0 | I2174: =VLOOKUP(A2174,'Medical Examinations'!A$1:H4508,8,0) -> NO | J2174: =VLOOKUP(A2174,'Medical Examinations'!A$1:J4509,10,0) -> Obesity | K2174: =VLOOKUP(A2174,'Medical Examinations'!A$1:K4508,11,0) -> Diabetes | L2174: =VLOOKUP(A2174,'Hospitalisation Details'!A$1:L4516,12,0) -> 13-Dec-2002 | M2174: =VLOOKUP(A2174,'Hospitalisation Details'!A$1:F4517,6,0) -> 1769.53 | N2174: =VLOOKUP(A2174,'Hospitalisation Details'!A$1:G4516,7,0) -> tier - 3 | O2174: =VLOOKUP(A2174,'Hospitalisation Details'!A$1:H4517,8,0) -> tier - 3 | P2174: =VLOOKUP(A2174,'Hospitalisation Details'!A$1:I4517,9,0) -> R1012 | Q2174: =VLOOKUP(A2174,'Hospitalisation Details'!A$1:M4517,13,0) -> 20
A2175: Id2174 | B2175: =VLOOKUP(A2175,'Customer Names'!A$1:D4510,4,0) -> O'Brien | C2175: =VLOOKUP(A2175,'Medical Examinations'!A$1:B4510,2,0) -> 40.5 | D2175: =VLOOKUP(A2175,'Medical Examinations'!A$1:C4511,3,0) -> 5.4 | E2175: =VLOOKUP(A2175,'Medical Examinations'!A$1:D4510,4,0) -> NO | F2175: =VLOOKUP(A2175,'Medical Examinations'!A$1:E4510,5,0) -> NO | G2175: =VLOOKUP(A2175,'Medical Examinations'!A$1:F4510,6,0) -> Yes | H2175: =VLOOKUP(A2175,'Medical Examinations'!A$1:G4510,7,0) -> 1 | I2175: =VLOOKUP(A2175,'Medical Examinations'!A$1:H4509,8,0) -> NO | J2175: =VLOOKUP(A2175,'Medical Examinations'!A$1:J4510,10,0) -> Over Weight | K2175: =VLOOKUP(A2175,'Medical Examinations'!A$1:K4509,11,0) -> Normal | L2175: =VLOOKUP(A2175,'Hospitalisation Details'!A$1:L4517,12,0) -> 19-Nov-2003 | M2175: =VLOOKUP(A2175,'Hospitalisation Details'!A$1:F4518,6,0) -> 1759.34 | N2175: =VLOOKUP(A2175,'Hospitalisation Details'!A$1:G4517,7,0) -> tier - 3 | O2175: =VLOOKUP(A2175,'Hospitalisation Details'!A$1:H4518,8,0) -> tier - 1 | P2175: UNKNOWN | Q2175: =VLOOKUP(A2175,'Hospitalisation Details'!A$1:M4518,13,0) -> 19
A2176: Id2175 | B2176: =VLOOKUP(A2176,'Customer Names'!A$1:D4511,4,0) -> Rodas | C2176: =VLOOKUP(A2176,'Medical Examinations'!A$1:B4511,2,0) -> 25.64 | D2176: =VLOOKUP(A2176,'Medical Examinations'!A$1:C4512,3,0) -> 4.76 | E2176: =VLOOKUP(A2176,'Medical Examinations'!A$1:D4511,4,0) -> NO | F2176: =VLOOKUP(A2176,'Medical Examinations'!A$1:E4511,5,0) -> NO | G2176: =VLOOKUP(A2176,'Medical Examinations'!A$1:F4511,6,0) -> NO | H2176: =VLOOKUP(A2176,'Medical Examinations'!A$1:G4511,7,0) -> 1 | I2176: =VLOOKUP(A2176,'Medical Examinations'!A$1:H4510,8,0) -> NO | J2176: =VLOOKUP(A2176,'Medical Examinations'!A$1:J4511,10,0) -> Obesity | K2176: =VLOOKUP(A2176,'Medical Examinations'!A$1:K4510,11,0) -> Normal | L2176: =VLOOKUP(A2176,'Hospitalisation Details'!A$1:L4518,12,0) -> 7-Oct-1998 | M2176: =VLOOKUP(A2176,'Hospitalisation Details'!A$1:F4519,6,0) -> 1756.6 | N2176: =VLOOKUP(A2176,'Hospitalisation Details'!A$1:G4518,7,0) -> tier - 3 | O2176: =VLOOKUP(A2176,'Hospitalisation Details'!A$1:H4519,8,0) -> tier - 3 | P2176: =VLOOKUP(A2176,'Hospitalisation Details'!A$1:I4519,9,0) -> R1013 | Q2176: =VLOOKUP(A2176,'Hospitalisation Details'!A$1:M4519,13,0) -> 24
A2177: Id2176 | B2177: =VLOOKUP(A2177,'Customer Names'!A$1:D4512,4,0) -> O'Connor | C2177: =VLOOKUP(A2177,'Medical Examinations'!A$1:B4512,2,0) -> 32.9 | D2177: =VLOOKUP(A2177,'Medical Examinations'!A$1:C4513,3,0) -> 4.78 | E2177: =VLOOKUP(A2177,'Medical Examinations'!A$1:D4512,4,0) -> NO | F2177: =VLOOKUP(A2177,'Medical Examinations'!A$1:E4512,5,0) -> NO | G2177: =VLOOKUP(A2177,'Medical Examinations'!A$1:F4512,6,0) -> Yes | H2177: =VLOOKUP(A2177,'Medical Examinations'!A$1:G4512,7,0) -> 1 | I2177: =VLOOKUP(A2177,'Medical Examinations'!A$1:H4511,8,0) -> NO | J2177: =VLOOKUP(A2177,'Medical Examinations'!A$1:J4512,10,0) -> Over Weight | K2177: =VLOOKUP(A2177,'Medical Examinations'!A$1:K4511,11,0) -> Normal | L2177: =VLOOKUP(A2177,'Hospitalisation Details'!A$1:L4519,12,0) -> 26-Sep-2003 | M2177: =VLOOKUP(A2177,'Hospitalisation Details'!A$1:F4520,6,0) -> 1748.77 | N2177: =VLOOKUP(A2177,'Hospitalisation Details'!A$1:G4519,7,0) -> tier - 3 | O2177: =VLOOKUP(A2177,'Hospitalisation Details'!A$1:H4520,8,0) -> tier - 1 | P2177: =VLOOKUP(A2177,'Hospitalisation Details'!A$1:I4520,9,0) -> R1011 | Q2177: =VLOOKUP(A2177,'Hospitalisation Details'!A$1:M4520,13,0) -> 19
A2178: Id2177 | B2178: =VLOOKUP(A2178,'Customer Names'!A$1:D4513,4,0) -> White | C2178: =VLOOKUP(A2178,'Medical Examinations'!A$1:B4513,2,0) -> 29.8 | D2178: =VLOOKUP(A2178,'Medical Examinations'!A$1:C4514,3,0) -> 4.26 | E2178: =VLOOKUP(A2178,'Medical Examinations'!A$1:D4513,4,0) -> NO | F2178: =VLOOKUP(A2178,'Medical Examinations'!A$1:E4513,5,0) -> NO | G2178: =VLOOKUP(A2178,'Medical Examinations'!A$1:F4513,6,0) -> Yes | H2178: =VLOOKUP(A2178,'Medical Examinations'!A$1:G4513,7,0) -> 1 | I2178: =VLOOKUP(A2178,'Medical Examinations'!A$1:H4512,8,0) -> NO | J2178: =VLOOKUP(A2178,'Medical Examinations'!A$1:J4513,10,0) -> Over Weight | K2178: =VLOOKUP(A2178,'Medical Examinations'!A$1:K4512,11,0) -> Normal | L2178: =VLOOKUP(A2178,'Hospitalisation Details'!A$1:L4520,12,0) -> 28-Jul-2003 | M2178: =VLOOKUP(A2178,'Hospitalisation Details'!A$1:F4521,6,0) -> 1744.47 | N2178: =VLOOKUP(A2178,'Hospitalisation Details'!A$1:G4520,7,0) -> tier - 3 | O2178: =VLOOKUP(A2178,'Hospitalisation Details'!A$1:H4521,8,0) -> tier - 1 | P2178: =VLOOKUP(A2178,'Hospitalisation Details'!A$1:I4521,9,0) -> R1011 | Q2178: =VLOOKUP(A2178,'Hospitalisation Details'!A$1:M4521,13,0) -> 19
A2179: Id2178 | B2179: =VLOOKUP(A2179,'Customer Names'!A$1:D4514,4,0) -> Davenport | C2179: =VLOOKUP(A2179,'Medical Examinations'!A$1:B4514,2,0) -> 28.9 | D2179: =VLOOKUP(A2179,'Medical Examinations'!A$1:C4515,3,0) -> 5.85 | E2179: =VLOOKUP(A2179,'Medical Examinations'!A$1:D4514,4,0) -> NO | F2179: =VLOOKUP(A2179,'Medical Examinations'!A$1:E4514,5,0) -> NO | G2179: =VLOOKUP(A2179,'Medical Examinations'!A$1:F4514,6,0) -> Yes | H2179: =VLOOKUP(A2179,'Medical Examinations'!A$1:G4514,7,0) -> 1 | I2179: =VLOOKUP(A2179,'Medical Examinations'!A$1:H4513,8,0) -> NO | J2179: =VLOOKUP(A2179,'Medical Examinations'!A$1:J4514,10,0) -> NormalWeight | K2179: =VLOOKUP(A2179,'Medical Examinations'!A$1:K4513,11,0) -> Pre-Diabetes | L2179: =VLOOKUP(A2179,'Hospitalisation Details'!A$1:L4521,12,0) -> 25-Jul-2003 | M2179: =VLOOKUP(A2179,'Hospitalisation Details'!A$1:F4522,6,0) -> 1743.21 | N2179: =VLOOKUP(A2179,'Hospitalisation Details'!A$1:G4521,7,0) -> tier - 3 | O2179: =VLOOKUP(A2179,'Hospitalisation Details'!A$1:H4522,8,0) -> tier - 1 | P2179: =VLOOKUP(A2179,'Hospitalisation Details'!A$1:I4522,9,0) -> R1011 | Q2179: =VLOOKUP(A2179,'Hospitalisation Details'!A$1:M4522,13,0) -> 19
A2180: Id2179 | B2180: =VLOOKUP(A2180,'Customer Names'!A$1:D4515,4,0) -> Karmen | C2180: =VLOOKUP(A2180,'Medical Examinations'!A$1:B4515,2,0) -> 24.7 | D2180: =VLOOKUP(A2180,'Medical Examinations'!A$1:C4516,3,0) -> 5.32 | E2180: =VLOOKUP(A2180,'Medical Examinations'!A$1:D4515,4,0) -> NO | F2180: =VLOOKUP(A2180,'Medical Examinations'!A$1:E4515,5,0) -> NO | G2180: =VLOOKUP(A2180,'Medical Examinations'!A$1:F4515,6,0) -> Yes | H2180: =VLOOKUP(A2180,'Medical Examinations'!A$1:G4515,7,0) -> 1 | I2180: =VLOOKUP(A2180,'Medical Examinations'!A$1:H4514,8,0) -> NO | J2180: =VLOOKUP(A2180,'Medical Examinations'!A$1:J4515,10,0) -> NormalWeight | K2180: =VLOOKUP(A2180,'Medical Examinations'!A$1:K4514,11,0) -> Normal | L2180: =VLOOKUP(A2180,'Hospitalisation Details'!A$1:L4522,12,0) -> 14-Nov-2003 | M2180: =VLOOKUP(A2180,'Hospitalisation Details'!A$1:F4523,6,0) -> 1737.38 | N2180: =VLOOKUP(A2180,'Hospitalisation Details'!A$1:G4522,7,0) -> tier - 3 | O2180: =VLOOKUP(A2180,'Hospitalisation Details'!A$1:H4523,8,0) -> tier - 2 | P2180: =VLOOKUP(A2180,'Hospitalisation Details'!A$1:I4523,9,0) -> R1011 | Q2180: =VLOOKUP(A2180,'Hospitalisation Details'!A$1:M4523,13,0) -> 19
A2181: Id2180 | B2181: =VLOOKUP(A2181,'Customer Names'!A$1:D4516,4,0) -> Miller | C2181: =VLOOKUP(A2181,'Medical Examinations'!A$1:B4516,2,0) -> 20.6 | D2181: =VLOOKUP(A2181,'Medical Examinations'!A$1:C4517,3,0) -> 5.14 | E2181: =VLOOKUP(A2181,'Medical Examinations'!A$1:D4516,4,0) -> NO | F2181: =VLOOKUP(A2181,'Medical Examinations'!A$1:E4516,5,0) -> NO | G2181: =VLOOKUP(A2181,'Medical Examinations'!A$1:F4516,6,0) -> Yes | H2181: =VLOOKUP(A2181,'Medical Examinations'!A$1:G4516,7,0) -> 1 | I2181: =VLOOKUP(A2181,'Medical Examinations'!A$1:H4515,8,0) -> NO | J2181: =VLOOKUP(A2181,'Medical Examinations'!A$1:J4516,10,0) -> NormalWeight | K2181: =VLOOKUP(A2181,'Medical Examinations'!A$1:K4515,11,0) -> Normal | L2181: =VLOOKUP(A2181,'Hospitalisation Details'!A$1:L4523,12,0) -> 9-Nov-2003 | M2181: =VLOOKUP(A2181,'Hospitalisation Details'!A$1:F4524,6,0) -> 1731.68 | N2181: =VLOOKUP(A2181,'Hospitalisation Details'!A$1:G4523,7,0) -> tier - 3 | O2181: =VLOOKUP(A2181,'Hospitalisation Details'!A$1:H4524,8,0) -> tier - 2 | P2181: =VLOOKUP(A2181,'Hospitalisation Details'!A$1:I4524,9,0) -> R1011 | Q2181: =VLOOKUP(A2181,'Hospitalisation Details'!A$1:M4524,13,0) -> 19
